Workbook

Sheet Index
C3: NAME: Aditi Singla College: FIIB, Delhi Roll No. 25PGDMFM047 Sector: Steel Industry Batch : F1,Aditya Birla Capital Ltd.

Sheet 1.Super Trend
A1: STEEL INDUSTRY (Super Trend Indicator BackTesting)
A3: BUY | I3: SELL
A5: Q1 (1 April 2025-30Jun 2025) | I5: Q1 (1 April 2025-30Jun 2025)
A6: Symbol | B6: Backtest P&L | C6: Total number of trades | D6: Number of wins | E6: Number of losses | I6: Symbol | J6: Backtest P&L | K6: Total number of trades | L6: Number of wins | M6: Number of losses
A7: JSWSTEEL | B7: -1447.29 | C7: 56 | D7: 22 | E7: 34 | I7: JSWSTEEL | J7: 1493.09 | K7: 51 | L7: 29 | M7: 22
A8: TATASTEEL | B8: 1894.24 | C8: 50 | D8: 26 | E8: 24 | I8: TATASTEEL | J8: -841.06 | K8: 55 | L8: 24 | M8: 31
A9: JINDALSTEEL | B9: 1241.5 | C9: 57 | D9: 27 | E9: 30 | I9: JINDALSTEEL | J9: -1289.7 | K9: 54 | L9: 21 | M9: 33
A10: SAIL | B10: 1690.89 | C10: 53 | D10: 27 | E10: 26 | I10: SAIL | J10: 758.15 | K10: 55 | L10: 28 | M10: 27
A11: JSL | B11: -1083.24 | C11: 52 | D11: 21 | E11: 31 | I11: JSL | J11: 909.99 | K11: 50 | L11: 22 | M11: 28
A12: NSLNSIP | B12: 585.18 | C12: 49 | D12: 20 | E12: 29 | I12: NSLNSIP | J12: 312.11 | K12: 54 | L12: 24 | M12: 30
A13: SARDAEN | B13: 373.55 | C13: 59 | D13: 24 | E13: 35 | I13: SARDAEN | J13: 2718.54 | K13: 56 | L13: 31 | M13: 25
A14: JAIBALAJI | B14: 223.57 | C14: 55 | D14: 21 | E14: 34 | I14: JAIBALAJI | J14: 1721.5 | K14: 54 | L14: 27 | M14: 27
A15: PRAKASH | B15: -401.43 | C15: 58 | D15: 20 | E15: 38 | I15: PRAKASH | J15: 2224.12 | K15: 56 | L15: 29 | M15: 27
A16: MUKANDLTD | B16: 987.71 | C16: 86 | D16: 35 | E16: 51 | I16: MUKANDLTD | J16: -3199.31 | K16: 77 | L16: 24 | M16: 53
A17: TOTAL | C17: =SUM(C7:C16) -> 575 | D17: =SUM(D7:D16) -> 243 | E17: =SUM(E7:E16) -> 332 | I17: TOTAL | K17: =SUM(K7:K16) -> 562 | L17: =SUM(L7:L16) -> 259 | M17: =SUM(M7:M16) -> 303
A19: Q2 (2 Jul 2025-30Sep 2025) | I19: Q2 (2 Jul 2025-30Sep 2025)
A20: Symbol | B20: Backtest P&L | C20: Total number of trades | D20: Number of wins | E20: Number of losses | I20: Symbol | J20: Backtest P&L | K20: Total number of trades | L20: Number of wins | M20: Number of losses
A21: JSWSTEEL | B21: -306.95 | C21: 57 | D21: 30 | E21: 27 | I21: JSWSTEEL | J21: -377.94 | K21: 56 | L21: 24 | M21: 32
A22: TATASTEEL | B22: -559.7 | C22: 59 | D22: 25 | E22: 34 | I22: TATASTEEL | J22: -1909.74 | K22: 54 | L22: 24 | M22: 30
A23: JINDALSTEEL | B23: -845.19 | C23: 64 | D23: 27 | E23: 37 | I23: JINDALSTEEL | J23: -118.75 | K23: 60 | L23: 28 | M23: 32
A24: SAIL | B24: -1083 | C24: 60 | D24: 23 | E24: 37 | I24: SAIL | J24: -1113.79 | K24: 59 | L24: 28 | M24: 31
A25: JSL | B25: 2911.6 | C25: 58 | D25: 30 | E25: 28 | I25: JSL | J25: -2363.95 | K25: 60 | L25: 19 | M25: 41
A26: NSLNSIP | B26: -1201.93 | C26: 58 | D26: 23 | E26: 35 | I26: NSLNSIP | J26: 1684.44 | K26: 57 | L26: 29 | M26: 28
A27: SARDAEN | B27: -4391.49 | C27: 61 | D27: 12 | E27: 49 | I27: SARDAEN | J27: -1736.95 | K27: 57 | L27: 22 | M27: 35
A28: JAIBALAJI | B28: -4277.41 | C28: 75 | D28: 19 | E28: 56 | I28: JAIBALAJI | J28: 1923.98 | K28: 62 | L28: 30 | M28: 32
A29: PRAKASH | B29: -1650.3 | C29: 59 | D29: 18 | E29: 41 | I29: PRAKASH | J29: 2317.42 | K29: 62 | L29: 35 | M29: 27
A30: MUKANDLTD | B30: -821.43 | C30: 67 | D30: 24 | E30: 43 | I30: MUKANDLTD | J30: 179.53 | K30: 68 | L30: 28 | M30: 40
A31: TOTAL | C31: =SUM(C21:C30) -> 618 | D31: =SUM(D21:D30) -> 231 | E31: =SUM(E21:E30) -> 387 | I31: TOTAL | K31: =SUM(K21:K30) -> 595 | L31: =SUM(L21:L30) -> 267 | M31: =SUM(M21:M30) -> 328
A33: Q3 (1Oct 2025- 30Dec 2025) | I33: Q3 (1Oct 2025- 30Dec 2025)
A34: Symbol | B34: Backtest P&L | C34: Total number of trades | D34: Number of wins | E34: Number of losses | I34: Symbol | J34: Backtest P&L | K34: Total number of trades | L34: Number of wins | M34: Number of losses
A35: JSWSTEEL | B35: -126.59 | C35: 47 | D35: 25 | E35: 22 | I35: JSWSTEEL | J35: -19.55 | K35: 50 | L35: 22 | M35: 28
A36: TATASTEEL | B36: 385.3 | C36: 46 | D36: 18 | E36: 28 | I36: TATASTEEL | J36: 738.44 | K36: 44 | L36: 19 | M36: 25
A37: JINDALSTEEL | B37: 1820.4 | C37: 55 | D37: 29 | E37: 26 | I37: JINDALSTEEL | J37: 187.09 | K37: 45 | L37: 21 | M37: 24
A38: SAIL | B38: -1398.55 | C38: 56 | D38: 26 | E38: 30 | I38: SAIL | J38: 1305.13 | K38: 52 | L38: 27 | M38: 25
A39: JSL | B39: -156.04 | C39: 55 | D39: 27 | E39: 28 | I39: JSL | J39: -182.05 | K39: 57 | L39: 25 | M39: 32
A40: NSLNSIP | B40: 883.62 | C40: 55 | D40: 22 | E40: 33 | I40: NSLNSIP | J40: 1418.55 | K40: 49 | L40: 29 | M40: 20
A41: SARDAEN | B41: -550.29 | C41: 58 | D41: 23 | E41: 35 | I41: SARDAEN | J41: 3544.84 | K41: 53 | L41: 27 | M41: 26
A42: JAIBALAJI | B42: -1643.38 | C42: 56 | D42: 18 | E42: 38 | I42: JAIBALAJI | J42: 3159.36 | K42: 54 | L42: 32 | M42: 22
A43: PRAKASH | B43: -1483.69 | C43: 59 | D43: 22 | E43: 37 | I43: PRAKASH | J43: 2995.38 | K43: 54 | L43: 34 | M43: 20
A44: MUKANDLTD | B44: -3194.11 | C44: 77 | D44: 26 | E44: 51 | I44: MUKANDLTD | J44: -2606.27 | K44: 73 | L44: 26 | M44: 47
...

Sheet 2.RSI
A1: STEEL INDUSTRY (RSI Indiactor Back Testing)
A3: BUY | I3: SELL
A5: Q1 (1 April 2025-30Jun 2025) | I5: Q1 (1 April 2025-30Jun 2025)
A6: Symbol | B6: Backtest P&L | C6: Total number of trades | D6: Number of wins | E6: Number of losses | I6: Symbol | J6: Backtest P&L | K6: Total number of trades | L6: Number of wins | M6: Number of losses
A7: JSWSTEEL | B7: 385.65 | C7: 45 | D7: 20 | E7: 25 | I7: JSWSTEEL | J7: 1472.89 | K7: 38 | L7: 22 | M7: 16
A8: TATASTEEL | B8: -187.32 | C8: 31 | D8: 12 | E8: 19 | I8: TATASTEEL | J8: 1531.55 | K8: 48 | L8: 25 | M8: 23
A9: JINDALSTEEL | B9: =-2003.24 -> -2003.24 | C9: 59 | D9: 19 | E9: 40 | I9: JINDALSTEEL | J9: -273.7 | K9: 45 | L9: 21 | M9: 24
A10: SAIL | B10: 601.65 | C10: 43 | D10: 16 | E10: 27 | I10: SAIL | J10: 1118.83 | K10: 52 | L10: 24 | M10: 28
A11: JSL | B11: -2735.229 | C11: 52 | D11: 18 | E11: 34 | I11: JSL | J11: -1677.05 | K11: 62 | L11: 19 | M11: 43
A12: NSLNSIP | B12: -12.33 | C12: 41 | D12: 17 | E12: 24 | I12: NSLNSIP | J12: -1140.39 | K12: 57 | L12: 22 | M12: 35
A13: SARDAEN | B13: -833.19 | C13: 70 | D13: 27 | E13: 43 | I13: SARDAEN | J13: 2605.99 | K13: 50 | L13: 25 | M13: 25
A14: JAIBALAJI | B14: -793.7 | C14: 52 | D14: 18 | E14: 34 | I14: JAIBALAJI | J14: 93.47 | K14: 52 | L14: 19 | M14: 33
A15: PRAKASH | B15: 49.54 | C15: 47 | D15: 16 | E15: 31 | I15: PRAKASH | J15: 2459.45 | K15: 49 | L15: 24 | M15: 25
A16: MUKANDLTD | B16: 773.51 | C16: 31 | D16: 11 | E16: 20 | I16: MUKANDLTD | J16: -861 | K16: 63 | L16: 24 | M16: 39
A17: TOTAL | C17: =SUM(C7:C16) -> 471 | D17: =SUM(D7:D16) -> 174 | E17: =SUM(E7:E16) -> 297 | I17: TOTAL | K17: =SUM(K7:K16) -> 516 | L17: =SUM(L7:L16) -> 225 | M17: =SUM(M7:M16) -> 291
A19: Q2 (2 Jul 2025-30Sep 2025) | I19: Q2 (2 Jul 2025-30Sep 2025)
A20: Symbol | B20: Backtest P&L | C20: Total number of trades | D20: Number of wins | E20: Number of losses | I20: Symbol | J20: Backtest P&L | K20: Total number of trades | L20: Number of wins | M20: Number of losses
A21: JSWSTEEL | B21: -182.85 | C21: 28 | D21: 17 | E21: 11 | I21: JSWSTEEL | J21: -502.7 | K21: 47 | L21: 23 | M21: 24
A22: TATASTEEL | B22: -1755.78 | C22: 33 | D22: 14 | E22: 19 | I22: TATASTEEL | J22: -1480.96 | K22: 43 | L22: 19 | M22: 24
A23: JINDALSTEEL | B23: -2362.04 | C23: 40 | D23: 13 | E23: 27 | I23: JINDALSTEEL | J23: -665.65 | K23: 50 | L23: 21 | M23: 29
A24: SAIL | B24: 17.93 | C24: 40 | D24: 19 | E24: 21 | I24: SAIL | J24: 1182.8 | K24: 50 | L24: 25 | M24: 25
A25: JSL | B25: -1398.39 | C25: 48 | D25: 17 | E25: 31 | I25: JSL | J25: -1144.85 | K25: 58 | L25: 22 | M25: 36
A26: NSLNSIP | B26: -510.19 | C26: 36 | D26: 16 | E26: 20 | I26: NSLNSIP | J26: 1075.79 | K26: 51 | L26: 25 | M26: 26
A27: SARDAEN | B27: -1260.84 | C27: 39 | D27: 16 | E27: 23 | I27: SARDAEN | J27: 2841.14 | K27: 47 | L27: 26 | M27: 21
A28: JAIBALAJI | B28: -295.85 | C28: 46 | D28: 18 | E28: 28 | I28: JAIBALAJI | J28: 1947.9 | K28: 41 | L28: 20 | M28: 21
A29: PRAKASH | B29: -1651.26 | C29: 38 | D29: 11 | E29: 27 | I29: PRAKASH | J29: 2979.59 | K29: 46 | L29: 26 | M29: 20
A30: MUKANDLTD | B30: -1878.4 | C30: 58 | D30: 20 | E30: 38 | I30: MUKANDLTD | J30: 5317.06 | K30: 48 | L30: 27 | M30: 21
A31: TOTAL | C31: =SUM(C21:C30) -> 406 | D31: =SUM(D21:D30) -> 161 | E31: =SUM(E21:E30) -> 245 | I31: TOTAL | K31: =SUM(K21:K30) -> 481 | L31: =SUM(L21:L30) -> 234 | M31: =SUM(M21:M30) -> 247
A33: Q3 (1Oct 2025- 30Dec 2025) | I33: Q3 (1Oct 2025- 30Dec 2025)
A34: Symbol | B34: Backtest P&L | C34: Total number of trades | D34: Number of wins | E34: Number of losses | I34: Symbol | J34: Backtest P&L | K34: Total number of trades | L34: Number of wins | M34: Number of losses
A35: JSWSTEEL | B35: -1871.39 | C35: 47 | D35: 21 | E35: 26 | I35: JSWSTEEL | J35: -408.85 | K35: 35 | L35: 17 | M35: 18
A36: TATASTEEL | B36: -1278.69 | C36: 43 | D36: 17 | E36: 26 | I36: TATASTEEL | J36: -306 | K36: 36 | L36: 16 | M36: 20
A37: JINDALSTEEL | B37: -1156.64 | C37: 49 | D37: 20 | E37: 29 | I37: JINDALSTEEL | J37: 392.89 | K37: 38 | L37: 18 | M37: 20
A38: SAIL | B38: 2328.01 | C38: 54 | D38: 29 | E38: 25 | I38: SAIL | J38: 4403.51 | K38: 51 | L38: 32 | M38: 19
A39: JSL | B39: 303.6 | C39: 39 | D39: 18 | E39: 21 | I39: JSL | J39: -626.05 | K39: 45 | L39: 21 | M39: 24
A40: NSLNSIP | B40: 10.68 | C40: 45 | D40: 17 | E40: 28 | I40: NSLNSIP | J40: 776.19 | K40: 54 | L40: 24 | M40: 30
A41: SARDAEN | B41: -777.39 | C41: 40 | D41: 14 | E41: 26 | I41: SARDAEN | J41: -442.75 | K41: 47 | L41: 20 | M41: 27
A42: JAIBALAJI | B42: -2420.05 | C42: 55 | D42: 21 | E42: 34 | I42: JAIBALAJI | J42: 1454.36 | K42: 41 | L42: 22 | M42: 19
A43: PRAKASH | B43: -1633.32 | C43: 50 | D43: 16 | E43: 34 | I43: PRAKASH | J43: 835.18 | K43: 47 | L43: 20 | M43: 27
A44: MUKANDLTD | B44: 1971.61 | C44: 29 | D44: 17 | E44: 12 | I44: MUKANDLTD | J44: 219.35 | K44: 43 | L44: 20 | M44: 23
...

Sheet 3. Fibonacci MA
A1: STEEL INDUSTRY (Moving Average Indicator BackTesting )
A3: BUY | I3: SELL
A5: Q1 (1 April 2025-30Jun 2025) | I5: Q1 (1 April 2025-30Jun 2025)
A6: Symbol | B6: Backtest P&L | C6: Total number of trades | D6: Number of wins | E6: Number of losses | I6: Symbol | J6: Backtest P&L | K6: Total number of trades | L6: Number of wins | M6: Number of losses
A7: JSWSTEEL | B7: -1424.99 | C7: 42 | D7: 17 | E7: 25 | I7: JSWSTEEL | J7: 357.59 | K7: 42 | L7: 22 | M7: 20
A8: TATASTEEL | B8: -421.42 | C8: 44 | D8: 20 | E8: 24 | I8: TATASTEEL | J8: -781.03 | K8: 43 | L8: 19 | M8: 24
A9: JINDALSTEEL | B9: -859.09 | C9: 37 | D9: 12 | E9: 25 | I9: JINDALSTEEL | J9: 1028.79 | K9: 40 | L9: 21 | M9: 19
A10: SAIL | B10: 1028.09 | C10: 45 | D10: 23 | E10: 22 | I10: SAIL | J10: 1012.08 | K10: 44 | L10: 20 | M10: 24
A11: JSL | B11: 636.35 | C11: 42 | D11: 18 | E11: 24 | I11: JSL | J11: -1713.55 | K11: 39 | L11: 12 | M11: 27
A12: NSLNSIP | B12: -181.22 | C12: 36 | D12: 12 | E12: 24 | I12: NSLNSIP | J12: 746.01 | K12: 38 | L12: 23 | M12: 15
A13: SARDAEN | B13: -3717.64 | C13: 47 | D13: 13 | E13: 34 | I13: SARDAEN | J13: 311.09 | K13: 46 | L13: 20 | M13: 26
A14: JAIBALAJI | B14: 183.64 | C14: 44 | D14: 19 | E14: 25 | I14: JAIBALAJI | J14: 2067.43 | K14: 45 | L14: 23 | M14: 22
A15: PRAKASH | B15: -2206.8 | C15: 41 | D15: 14 | E15: 27 | I15: PRAKASH | J15: 2344.6 | K15: 43 | L15: 25 | M15: 18
A16: MUKANDLTD | B16: 2969.08 | C16: 44 | D16: 23 | E16: 21 | I16: MUKANDLTD | J16: 315.76 | K16: 43 | L16: 17 | M16: 26
A17: TOTAL | C17: =SUM(C7:C16) -> 422 | D17: =SUM(D7:D16) -> 171 | E17: =SUM(E7:E16) -> 251 | I17: TOTAL | K17: =SUM(K7:K16) -> 423 | L17: =SUM(L7:L16) -> 202 | M17: =SUM(M7:M16) -> 221
A19: Q2 (2 Jul 2025-30Sep 2025) | I19: Q2 (2 Jul 2025-30Sep 2025)
A20: Symbol | B20: Backtest P&L | C20: Total number of trades | D20: Number of wins | E20: Number of losses | I20: Symbol | J20: Backtest P&L | K20: Total number of trades | L20: Number of wins | M20: Number of losses
A21: JSWSTEEL | B21: 107.99 | C21: 47 | D21: 22 | E21: 25 | I21: JSWSTEEL | J21: -895.74 | K21: 48 | L21: 20 | M21: 28
A22: TATASTEEL | B22: -1113.91 | C22: 42 | D22: 14 | E22: 28 | I22: TATASTEEL | J22: 436.61 | K22: 42 | L22: 23 | M22: 19
A23: JINDALSTEEL | B23: 211.34 | C23: 42 | D23: 22 | E23: 20 | I23: JINDALSTEEL | J23: -35.1 | K23: 40 | L23: 16 | M23: 24
A24: SAIL | B24: -216.002 | C24: 43 | D24: 20 | E24: 23 | I24: SAIL | J24: 701.05 | K24: 47 | L24: 22 | M24: 25
A25: JSL | B25: 581.45 | C25: 46 | D25: 20 | E25: 26 | I25: JSL | J25: -875.3 | K25: 45 | L25: 17 | M25: 28
A26: NSLNSIP | B26: -1275.81 | C26: 48 | D26: 18 | E26: 30 | I26: NSLNSIP | J26: 261.07 | K26: 49 | L26: 22 | M26: 27
A27: SARDAEN | B27: -707.64 | C27: 47 | D27: 16 | E27: 31 | I27: SARDAEN | J27: 750.69 | K27: 44 | L27: 19 | M27: 25
A28: JAIBALAJI | B28: -2904.82 | C28: 51 | D28: 13 | E28: 38 | I28: JAIBALAJI | J28: 1244.85 | K28: 43 | L28: 20 | M28: 23
A29: PRAKASH | B29: -70.32 | C29: 49 | D29: 18 | E29: 31 | I29: PRAKASH | J29: -531.25 | K29: 52 | L29: 24 | M29: 28
A30: MUKANDLTD | B30: -1712.54 | C30: 46 | D30: 13 | E30: 33 | I30: MUKANDLTD | J30: 2630.75 | K30: 46 | L30: 26 | M30: 20
A31: TOTAL | C31: =SUM(C21:C30) -> 461 | D31: =SUM(D21:D30) -> 176 | E31: =SUM(E21:E30) -> 285 | I31: TOTAL | K31: =SUM(K21:K30) -> 456 | L31: =SUM(L21:L30) -> 209 | M31: =SUM(M21:M30) -> 247
A33: Q3 (1Oct 2025- 30Dec 2025) | I33: Q3 (1Oct 2025- 30Dec 2025)
A34: Symbol | B34: Backtest P&L | C34: Total number of trades | D34: Number of wins | E34: Number of losses | I34: Symbol | J34: Backtest P&L | K34: Total number of trades | L34: Number of wins | M34: Number of losses
A35: JSWSTEEL | B35: 265.2 | C35: 42 | D35: 20 | E35: 22 | I35: JSWSTEEL | J35: -879.6 | K35: 42 | L35: 15 | M35: 27
A36: TATASTEEL | B36: 664.96 | C36: 39 | D36: 22 | E36: 17 | I36: TATASTEEL | J36: 171.76 | K36: 37 | L36: 16 | M36: 21
A37: JINDALSTEEL | B37: 149.6 | C37: 38 | D37: 20 | E37: 18 | I37: JINDALSTEEL | J37: 1028.69 | K37: 42 | L37: 19 | M37: 23
A38: SAIL | B38: 718.57 | C38: 45 | D38: 22 | E38: 23 | I38: SAIL | J38: -1073.28 | K38: 51 | L38: 24 | M38: 27
A39: JSL | B39: -767.59 | C39: 43 | D39: 19 | E39: 24 | I39: JSL | J39: -97.05 | K39: 41 | L39: 21 | M39: 20
A40: NSLNSIP | B40: -809.81 | C40: 37 | D40: 17 | E40: 20 | I40: NSLNSIP | J40: 1854.38 | K40: 35 | L40: 28 | M40: 7
A41: SARDAEN | B41: 210.3 | C41: 41 | D41: 19 | E41: 22 | I41: SARDAEN | J41: 2205.44 | K41: 41 | L41: 25 | M41: 16
A42: JAIBALAJI | B42: 769.35 | C42: 47 | D42: 21 | E42: 26 | I42: JAIBALAJI | J42: 1980.55 | K42: 45 | L42: 21 | M42: 24
A43: PRAKASH | B43: -1331.32 | C43: 38 | D43: 12 | E43: 26 | I43: PRAKASH | J43: 2868.84 | K43: 37 | L43: 26 | M43: 11
A44: MUKANDLTD | B44: 760.26 | C44: 40 | D44: 18 | E44: 22 | I44: MUKANDLTD | J44: 729.53 | K44: 45 | L44: 24 | M44: 21
...

Sheet 4.VWAP
A1: STEEL INDUSTRY (VWAP Indicator BackTesting)
A3: BUY | I3: SELL
A5: Q1 (1 April 2025-30Jun 2025) | I5: Q1 (1 April 2025-30Jun 2025)
A6: Symbol | B6: Backtest P&L | C6: Total number of trades | D6: Number of wins | E6: Number of losses | I6: Symbol | J6: Backtest P&L | K6: Total number of trades | L6: Number of wins | M6: Number of losses
A7: JSWSTEEL | B7: -2249.19 | C7: 82 | D7: 28 | E7: 54 | I7: JSWSTEEL | J7: 2883.19 | K7: 78 | L7: 42 | M7: 36
A8: TATASTEEL | B8: 2504.37 | C8: 75 | D8: 37 | E8: 38 | I8: TATASTEEL | J8: -3827.31 | K8: 90 | L8: 30 | M8: 60
A9: JINDALSTEEL | B9: 3177.15 | C9: 87 | D9: 37 | E9: 50 | I9: JINDALSTEEL | J9: -3394.1 | K9: 99 | L9: 35 | M9: 64
A10: SAIL | B10: 1875.12 | C10: 92 | D10: 39 | E10: 53 | I10: SAIL | J10: -1692.99 | K10: 98 | L10: 36 | M10: 62
A11: JSL | B11: -758.09 | C11: 108 | D11: 40 | E11: 68 | I11: JSL | J11: -1948.75 | K11: 110 | L11: 38 | M11: 72
A12: NSLNSIP | B12: 3366.21 | C12: 81 | D12: 41 | E12: 40 | I12: NSLNSIP | J12: -736.65 | K12: 94 | L12: 36 | M12: 58
A13: SARDAEN | B13: -3183.74 | C13: 122 | D13: 42 | E13: 80 | I13: SARDAEN | J13: 394.29 | K13: 117 | L13: 46 | M13: 71
A14: JAIBALAJI | B14: -1111.49 | C14: 108 | D14: 38 | E14: 70 | I14: JAIBALAJI | J14: 5005.11 | K14: 115 | L14: 56 | M14: 59
A15: PRAKASH | B15: -1624 | C15: 103 | D15: 34 | E15: 69 | I15: PRAKASH | J15: 1945.7 | K15: 113 | L15: 44 | M15: 69
A16: MUKANDLTD | B16: 809.6 | C16: 134 | D16: 51 | E16: 83 | I16: MUKANDLTD | J16: -5260.17 | K16: 133 | L16: 42 | M16: 91
A17: TOTAL | C17: =SUM(C7:C16) -> 992 | D17: =SUM(D7:D16) -> 387 | E17: =SUM(E7:E16) -> 605 | I17: TOTAL | K17: =SUM(K7:K16) -> 1047 | L17: =SUM(L7:L16) -> 405 | M17: =SUM(M7:M16) -> 642
A19: Q2 (2 Jul 2025-30Sep 2025) | I19: Q2 (2 Jul 2025-30Sep 2025)
A20: Symbol | B20: Backtest P&L | C20: Total number of trades | D20: Number of wins | E20: Number of losses | I20: Symbol | J20: Backtest P&L | K20: Total number of trades | L20: Number of wins | M20: Number of losses
A21: JSWSTEEL | B21: 50.59 | C21: 75 | D21: 39 | E21: 36 | I21: JSWSTEEL | J21: -309.49 | K21: 77 | L21: 38 | M21: 39
A22: TATASTEEL | B22: -1284.52 | C22: 75 | D22: 29 | E22: 46 | I22: TATASTEEL | J22: 322.66 | K22: 68 | L22: 37 | M22: 31
A23: JINDALSTEEL | B23: -1321.24 | C23: 92 | D23: 36 | E23: 56 | I23: JINDALSTEEL | J23: 477.09 | K23: 87 | L23: 38 | M23: 49
A24: SAIL | B24: -55.1 | C24: 84 | D24: 32 | E24: 52 | I24: SAIL | J24: 103.62 | K24: 89 | L24: 39 | M24: 50
A25: JSL | B25: 1080.5 | C25: 89 | D25: 38 | E25: 51 | I25: JSL | J25: -992.6 | K25: 89 | L25: 34 | M25: 55
A26: NSLNSIP | B26: -2931.18 | C26: 106 | D26: 35 | E26: 71 | I26: NSLNSIP | J26: 3020.02 | K26: 100 | L26: 48 | M26: 52
A27: SARDAEN | B27: -871.14 | C27: 110 | D27: 37 | E27: 73 | I27: SARDAEN | J27: 311.99 | K27: 106 | L27: 45 | M27: 61
A28: JAIBALAJI | B28: -6401.21 | C28: 112 | D28: 28 | E28: 84 | I28: JAIBALAJI | J28: 2935.81 | K28: 111 | L28: 51 | M28: 60
A29: PRAKASH | B29: 3650.25 | C29: 112 | D29: 46 | E29: 66 | I29: PRAKASH | J29: -982.14 | K29: 131 | L29: 57 | M29: 74
A30: MUKANDLTD | B30: -8908.79 | C30: 146 | D30: 36 | E30: 110 | I30: MUKANDLTD | J30: 1471.22 | K30: 133 | L30: 53 | M30: 80
A31: TOTAL | C31: =SUM(C21:C30) -> 1001 | D31: =SUM(D21:D30) -> 356 | E31: =SUM(E21:E30) -> 645 | I31: TOTAL | K31: =SUM(K21:K30) -> 991 | L31: =SUM(L21:L30) -> 440 | M31: =SUM(M21:M30) -> 551
A33: Q3 (1Oct 2025- 30Dec 2025) | I33: Q3 (1Oct 2025- 30Dec 2025)
A34: Symbol | B34: Backtest P&L | C34: Total number of trades | D34: Number of wins | E34: Number of losses | I34: Symbol | J34: Backtest P&L | K34: Total number of trades | L34: Number of wins | M34: Number of losses
A35: JSWSTEEL | B35: -1879.84 | C35: 81 | D35: 30 | E35: 51 | I35: JSWSTEEL | J35: 1126 | K35: 76 | L35: 37 | M35: 39
A36: TATASTEEL | B36: -884.79 | C36: 68 | D36: 29 | E36: 39 | I36: TATASTEEL | J36: 2297.1 | K36: 67 | L36: 34 | M36: 33
A37: JINDALSTEEL | B37: -980.54 | C37: 79 | D37: 35 | E37: 44 | I37: JINDALSTEEL | J37: -29.6 | K37: 79 | L37: 31 | M37: 48
A38: SAIL | B38: -1194.52 | C38: 82 | D38: 33 | E38: 49 | I38: SAIL | J38: 3916.2 | K38: 77 | L38: 37 | M38: 40
A39: JSL | B39: -809.39 | C39: 848 | D39: 35 | E39: 49 | I39: JSL | J39: 1151.89 | K39: 78 | L39: 33 | M39: 45
A40: NSLNSIP | B40: 3121.1 | C40: 88 | D40: 40 | E40: 48 | I40: NSLNSIP | J40: 1551.86 | K40: 82 | L40: 38 | M40: 44
A41: SARDAEN | B41: -605.14 | C41: 102 | D41: 34 | E41: 68 | I41: SARDAEN | J41: 2442.74 | K41: 94 | L41: 44 | M41: 50
A42: JAIBALAJI | B42: -2132.83 | C42: 98 | D42: 32 | E42: 66 | I42: JAIBALAJI | J42: 3702.76 | K42: 99 | L42: 46 | M42: 53
A43: PRAKASH | B43: -1128.52 | C43: 88 | D43: 32 | E43: 56 | I43: PRAKASH | J43: 3287.37 | K43: 91 | L43: 47 | M43: 44
A44: MUKANDLTD | B44: -2594.6 | C44: 108 | D44: 35 | E44: 73 | I44: MUKANDLTD | J44: 2193.9 | K44: 99 | L44: 44 | M44: 55
...

Sheet 5.MACD
A1: STEEL INDUSTRY (MACD Indicator BackTesting)
A3: BUY | I3: SELL
A5: Q1 (1 April 2025-30Jun 2025) | I5: Q1 (1 April 2025-30Jun 2025)
A6: Symbol | B6: Backtest P&L | C6: Total number of trades | D6: Number of wins | E6: Number of losses | I6: Symbol | J6: Backtest P&L | K6: Total number of trades | L6: Number of wins | M6: Number of losses
A7: JSWSTEEL | B7: -1457.99 | C7: 93 | D7: 33 | E7: 60 | I7: JSWSTEEL | J7: 1376.39 | K7: 87 | L7: 49 | M7: 38
A8: TATASTEEL | B8: 2065.73 | C8: 93 | D8: 44 | E8: 49 | I8: TATASTEEL | J8: -758.26 | K8: 90 | L8: 41 | M8: 49
A9: JINDALSTEEL | B9: 496.8 | C9: 108 | D9: 45 | E9: 63 | I9: JINDALSTEEL | J9: -22.9 | K9: 102 | L9: 46 | M9: 56
A10: SAIL | B10: 2285.03 | C10: 109 | D10: 49 | E10: 60 | I10: SAIL | J10: -659.15 | K10: 106 | L10: 43 | M10: 63
A11: JSL | B11: 1758.45 | C11: 111 | D11: 51 | E11: 60 | I11: JSL | J11: -805.7 | K11: 106 | L11: 41 | M11: 65
A12: NSLNSIP | B12: 2908.97 | C12: 102 | D12: 47 | E12: 55 | I12: NSLNSIP | J12: -350.49 | K12: 107 | L12: 47 | M12: 60
A13: SARDAEN | B13: -4092.24 | C13: 121 | D13: 42 | E13: 79 | I13: SARDAEN | J13: 6641.69 | K13: 111 | L13: 59 | M13: 52
A14: JAIBALAJI | B14: -431.28 | C14: 113 | D14: 42 | E14: 71 | I14: JAIBALAJI | J14: 4679.6 | K14: 108 | L14: 53 | M14: 55
A15: PRAKASH | B15: -2580.86 | C15: 117 | D15: 36 | E15: 81 | I15: PRAKASH | J15: 3433.32 | K15: 110 | L15: 51 | M15: 59
A16: MUKANDLTD | B16: 3405.08 | C16: 124 | D16: 54 | E16: 70 | I16: MUKANDLTD | J16: -5185.11 | K16: 124 | L16: 39 | M16: 85
A17: TOTAL | C17: =SUM(C7:C16) -> 1091 | D17: =SUM(D7:D16) -> 443 | E17: =SUM(E7:E16) -> 648 | I17: TOTAL | K17: =SUM(K7:K16) -> 1051 | L17: =SUM(L7:L16) -> 469 | M17: =SUM(M7:M16) -> 582
A19: Q2 (2 Jul 2025-30Sep 2025) | I19: Q2 (2 Jul 2025-30Sep 2025)
A20: Symbol | B20: Backtest P&L | C20: Total number of trades | D20: Number of wins | E20: Number of losses | I20: Symbol | J20: Backtest P&L | K20: Total number of trades | L20: Number of wins | M20: Number of losses
A21: JSWSTEEL | B21: -1052.5 | C21: 87 | D21: 42 | E21: 45 | I21: JSWSTEEL | J21: -765.29 | K21: 88 | L21: 44 | M21: 44
A22: TATASTEEL | B22: -1709.98 | C22: 88 | D22: 37 | E22: 51 | I22: TATASTEEL | J22: -129.68 | K22: 83 | L22: 42 | M22: 41
A23: JINDALSTEEL | B23: -979.84 | C23: 95 | D23: 43 | E23: 52 | I23: JINDALSTEEL | J23: -839.45 | K23: 94 | L23: 40 | M23: 54
A24: SAIL | B24: -865.98 | C24: 100 | D24: 44 | E24: 56 | I24: SAIL | J24: -1095.69 | K24: 88 | L24: 40 | M24: 48
A25: JSL | B25: 1630.7 | C25: 98 | D25: 48 | E25: 50 | I25: JSL | J25: -71.55 | K25: 98 | L25: 41 | M25: 57
A26: NSLNSIP | B26: -1789.03 | C26: 119 | D26: 50 | E26: 69 | I26: NSLNSIP | J26: 2903.9 | K26: 104 | L26: 55 | M26: 49
A27: SARDAEN | B27: -1945.04 | C27: 125 | D27: 44 | E27: 81 | I27: SARDAEN | J27: 2090.44 | K27: 109 | L27: 50 | M27: 59
A28: JAIBALAJI | B28: -6724.21 | C28: 126 | D28: 34 | E28: 92 | I28: JAIBALAJI | J28: 6473.63 | K28: 102 | L28: 54 | M28: 48
A29: PRAKASH | B29: -4335.81 | C29: 127 | D29: 38 | E29: 89 | I29: PRAKASH | J29: 2862.43 | K29: 115 | L29: 59 | M29: 56
A30: MUKANDLTD | B30: -3186.32 | C30: 132 | D30: 46 | E30: 86 | I30: MUKANDLTD | J30: 4377.72 | K30: 119 | L30: 59 | M30: 60
A31: TOTAL | C31: =SUM(C21:C30) -> 1097 | D31: =SUM(D21:D30) -> 426 | E31: =SUM(E21:E30) -> 671 | I31: TOTAL | K31: =SUM(K21:K30) -> 1000 | L31: =SUM(L21:L30) -> 484 | M31: =SUM(M21:M30) -> 516
A33: Q3 (1Oct 2025- 30Dec 2025) | I33: Q3 (1Oct 2025- 30Dec 2025)
A34: Symbol | B34: Backtest P&L | C34: Total number of trades | D34: Number of wins | E34: Number of losses | I34: Symbol | J34: Backtest P&L | K34: Total number of trades | L34: Number of wins | M34: Number of losses
A35: JSWSTEEL | B35: -209.79 | C35: 90 | D35: 41 | E35: 49 | I35: JSWSTEEL | J35: 743.54 | K35: 84 | L35: 40 | M35: 44
A36: TATASTEEL | B36: 547.35 | C36: 80 | D36: 40 | E36: 40 | I36: TATASTEEL | J36: 637.24 | K36: 83 | L36: 38 | M36: 45
A37: JINDALSTEEL | B37: 769.5 | C37: 93 | D37: 44 | E37: 49 | I37: JINDALSTEEL | J37: -551.75 | K37: 82 | L37: 36 | M37: 46
A38: SAIL | B38: 1274.13 | C38: 94 | D38: 45 | E38: 49 | I38: SAIL | J38: 2687.84 | K38: 91 | L38: 45 | M38: 46
A39: JSL | B39: 145.7 | C39: 87 | D39: 37 | E39: 50 | I39: JSL | J39: -1092.45 | K39: 88 | L39: 37 | M39: 51
A40: NSLNSIP | B40: 3187.99 | C40: 92 | D40: 44 | E40: 48 | I40: NSLNSIP | J40: 1838.85 | K40: 89 | L40: 46 | M40: 43
A41: SARDAEN | B41: -2483.09 | C41: 121 | D41: 43 | E41: 78 | I41: SARDAEN | J41: 2899.39 | K41: 107 | L41: 55 | M41: 52
A42: JAIBALAJI | B42: -621.19 | C42: 109 | D42: 42 | E42: 67 | I42: JAIBALAJI | J42: 4477.09 | K42: 104 | L42: 54 | M42: 50
A43: PRAKASH | B43: -3688.57 | C43: 104 | D43: 32 | E43: 72 | I43: PRAKASH | J43: 3472.92 | K43: 99 | L43: 51 | M43: 48
A44: MUKANDLTD | B44: -1945.41 | C44: 108 | D44: 42 | E44: 66 | I44: MUKANDLTD | J44: 3330.84 | K44: 100 | L44: 49 | M44: 51
...

Sheet 6.Stochastic RSI
A1: STEEL INDUSTRY (Stochastic RSI Indicator BackTesting)
A3: BUY | I3: SELL
A5: Q1 (1 April 2025-30Jun 2025) | I5: Q1 (1 April 2025-30Jun 2025)
A6: Symbol | B6: Backtest P&L | C6: Total number of trades | D6: Number of wins | E6: Number of losses | I6: Symbol | J6: Backtest P&L | K6: Total number of trades | L6: Number of wins | M6: Number of losses
A7: JSWSTEEL | B7: -3539.84 | C7: 99 | D7: 34 | E7: 65 | I7: JSWSTEEL | J7: 2860.34 | K7: 97 | L7: 51 | M7: 46
A8: TATASTEEL | B8: 981.69 | C8: 96 | D8: 46 | E8: 50 | I8: TATASTEEL | J8: -241.59 | K8: 102 | L8: 42 | M8: 60
A9: JINDALSTEEL | B9: -2973.24 | C9: 125 | D9: 41 | E9: 84 | I9: JINDALSTEEL | J9: 315.29 | K9: 111 | L9: 53 | M9: 58
A10: SAIL | B10: -158.86 | C10: 123 | D10: 53 | E10: 70 | I10: SAIL | J10: -332.92 | K10: 120 | L10: 50 | M10: 70
A11: JSL | B11: -558.49 | C11: 123 | D11: 50 | E11: 73 | I11: JSL | J11: -1127.2 | K11: 123 | L11: 44 | M11: 79
A12: NSLNSIP | B12: 1318.25 | C12: 116 | D12: 51 | E12: 65 | I12: NSLNSIP | J12: 318.54 | K12: 115 | L12: 52 | M12: 63
A13: SARDAEN | B13: -4166.09 | C13: 123 | D13: 45 | E13: 82 | I13: SARDAEN | J13: 2727.19 | K13: 135 | L13: 63 | M13: 72
A14: JAIBALAJI | B14: -4846.72 | C14: 147 | D14: 47 | E14: 100 | I14: JAIBALAJI | J14: 7133.12 | K14: 139 | L14: 74 | M14: 65
A15: PRAKASH | B15: -5033.43 | C15: 136 | D15: 41 | E15: 95 | I15: PRAKASH | J15: 2433.53 | K15: 140 | L15: 65 | M15: 75
A16: MUKANDLTD | B16: 4263.41 | C16: 147 | D16: 65 | E16: 82 | I16: MUKANDLTD | J16: 521.02 | K16: 129 | L16: 53 | M16: 76
A17: TOTAL | C17: =SUM(C7:C16) -> 1235 | D17: =SUM(D7:D16) -> 473 | E17: =SUM(E7:E16) -> 766 | I17: TOTAL | K17: =SUM(K7:K16) -> 1211 | L17: =SUM(L7:L16) -> 547 | M17: =SUM(M7:M16) -> 664
A19: Q2 (2 Jul 2025-30Sep 2025) | I19: Q2 (2 Jul 2025-30Sep 2025)
A20: Symbol | B20: Backtest P&L | C20: Total number of trades | D20: Number of wins | E20: Number of losses | I20: Symbol | J20: Backtest P&L | K20: Total number of trades | L20: Number of wins | M20: Number of losses
A21: JSWSTEEL | B21: 555.89 | C21: 86 | D21: 46 | E21: 40 | I21: JSWSTEEL | J21: 485.7 | K21: 86 | L21: 46 | M21: 40
A22: TATASTEEL | B22: -642.88 | C22: 88 | D22: 37 | E22: 51 | I22: TATASTEEL | J22: 578.72 | K22: 86 | L22: 45 | M22: 41
A23: JINDALSTEEL | B23: -126.59 | C23: 101 | D23: 48 | E23: 53 | I23: JINDALSTEEL | J23: -700.85 | K23: 97 | L23: 43 | M23: 54
A24: SAIL | B24: 599.01 | C24: 100 | D24: 46 | E24: 54 | I24: SAIL | J24: -181.72 | K24: 102 | L24: 48 | M24: 54
A25: JSL | B25: -643.59 | C25: 114 | D25: 45 | E25: 69 | I25: JSL | J25: -330.6 | K25: 109 | L25: 44 | M25: 65
A26: NSLNSIP | B26: -2865.32 | C26: 124 | D26: 47 | E26: 77 | I26: NSLNSIP | J26: 3930.14 | K26: 110 | L26: 57 | M26: 53
A27: SARDAEN | B27: -4541.84 | C27: 135 | D27: 43 | E27: 92 | I27: SARDAEN | J27: 3670.64 | K27: 123 | L27: 61 | M27: 62
A28: JAIBALAJI | B28: -7371.1 | C28: 135 | D28: 33 | E28: 102 | I28: JAIBALAJI | J28: 6381.57 | K28: 125 | L28: 64 | M28: 61
A29: PRAKASH | B29: -1816 | C29: 131 | D29: 47 | E29: 84 | I29: PRAKASH | J29: 6138.1 | K29: 123 | L29: 67 | M29: 56
A30: MUKANDLTD | B30: -5209.02 | C30: 147 | D30: 48 | E30: 99 | I30: MUKANDLTD | J30: 9936.03 | K30: 143 | L30: 75 | M30: 68
A31: TOTAL | C31: =SUM(C21:C30) -> 1161 | D31: =SUM(D21:D30) -> 440 | E31: =SUM(E21:E30) -> 721 | I31: TOTAL | K31: =SUM(K21:K30) -> 1104 | L31: =SUM(L21:L30) -> 550 | M31: =SUM(M21:M30) -> 554
A33: Q3 (1Oct 2025- 30Dec 2025) | I33: Q3 (1Oct 2025- 30Dec 2025)
A34: Symbol | B34: Backtest P&L | C34: Total number of trades | D34: Number of wins | E34: Number of losses | I34: Symbol | J34: Backtest P&L | K34: Total number of trades | L34: Number of wins | M34: Number of losses
A35: JSWSTEEL | B35: -1500.94 | C35: 88 | D35: 38 | E35: 50 | I35: JSWSTEEL | J35: 2389.74 | K35: 87 | L35: 45 | M35: 42
A36: TATASTEEL | B36: -1492.02 | C36: 85 | D36: 37 | E36: 48 | I36: TATASTEEL | J36: 1779.84 | K36: 84 | L36: 45 | M36: 39
A37: JINDALSTEEL | B37: -890.04 | C37: 105 | D37: 47 | E37: 58 | I37: JINDALSTEEL | J37: 1203.04 | K37: 92 | L37: 41 | M37: 51
A38: SAIL | B38: -401.68 | C38: 113 | D38: 52 | E38: 113 | I38: SAIL | J38: -839.47 | K38: 107 | L38: 42 | M38: 65
A39: JSL | B39: 1241.75 | C39: 100 | D39: 44 | E39: 56 | I39: JSL | J39: 1107.44 | K39: 96 | L39: 46 | M39: 50
A40: NSLNSIP | B40: 1255.51 | C40: 103 | D40: 47 | E40: 56 | I40: NSLNSIP | J40: -314.31 | K40: 105 | L40: 48 | M40: 57
A41: SARDAEN | B41: -1529.29 | C41: 111 | D41: 38 | E41: 73 | I41: SARDAEN | J41: 1222.89 | K41: 115 | L41: 56 | M41: 59
A42: JAIBALAJI | B42: -2295.14 | C42: 128 | D42: 51 | E42: 77 | I42: JAIBALAJI | J42: 3675.8 | K42: 117 | L42: 56 | M42: 61
A43: PRAKASH | B43: -3001.54 | C43: 117 | D43: 44 | E43: 73 | I43: PRAKASH | J43: 6364.53 | K43: 105 | L43: 58 | M43: 47
A44: MUKANDLTD | B44: -982.64 | C44: 107 | D44: 42 | E44: 65 | I44: MUKANDLTD | J44: 2290.55 | K44: 112 | L44: 50 | M44: 62
...

Sheet 7.Pivot Point Standard
A1: STEEL INDUSTRY (PIVOT Indicator BackTesting)
A3: BUY | I3: SELL
A5: Q1 (1 April 2025-30Jun 2025) | I5: Q1 (1 April 2025-30Jun 2025)
A6: Symbol | B6: Backtest P&L | C6: Total number of trades | D6: Number of wins | E6: Number of losses | I6: Symbol | J6: Backtest P&L | K6: Total number of trades | L6: Number of wins | M6: Number of losses
A7: JSWSTEEL | B7: 189.65 | C7: 29 | D7: 12 | E7: 17 | I7: JSWSTEEL | J7: 2692.94 | K7: 31 | L7: 19 | M7: 12
A8: TATASTEEL | B8: -29 | C8: 32 | D8: 12 | E8: 20 | I8: TATASTEEL | J8: 470.65 | K8: 35 | L8: 16 | M8: 19
A9: JINDALSTEEL | B9: -962.39 | C9: 28 | D9: 10 | E9: 18 | I9: JINDALSTEEL | J9: 817.74 | K9: 26 | L9: 13 | M9: 13
A10: SAIL | B10: 398.65 | C10: 35 | D10: 15 | E10: 20 | I10: SAIL | J10: 234.23 | K10: 39 | L10: 14 | M10: 25
A11: JSL | B11: 1346.85 | C11: 39 | D11: 17 | E11: 22 | I11: JSL | J11: -39.05 | K11: 42 | L11: 16 | M11: 26
A12: NSLNSIP | B12: -2394.14 | C12: 39 | D12: 11 | E12: 28 | I12: NSLNSIP | J12: 814.25 | K12: 43 | L12: 19 | M12: 24
A13: SARDAEN | B13: -897.29 | C13: 31 | D13: 10 | E13: 21 | I13: SARDAEN | J13: -385.75 | K13: 24 | L13: 14 | M13: 20
A14: JAIBALAJI | B14: 1315.66 | C14: 21 | D14: 9 | E14: 12 | I14: JAIBALAJI | J14: 293.95 | K14: 24 | L14: 9 | M14: 15
A15: PRAKASH | B15: 951.76 | C15: 27 | D15: 11 | E15: 16 | I15: PRAKASH | J15: 1770.75 | K15: 33 | L15: 15 | M15: 18
A16: MUKANDLTD | B16: 327.68 | C16: 37 | D16: 16 | E16: 21 | I16: MUKANDLTD | J16: -283.15 | K16: 43 | L16: 16 | M16: 27
A17: TOTAL | C17: =SUM(C7:C16) -> 318 | D17: =SUM(D7:D16) -> 123 | E17: =SUM(E7:E16) -> 195 | I17: TOTAL | K17: =SUM(K7:K16) -> 340 | L17: =SUM(L7:L16) -> 151 | M17: =SUM(M7:M16) -> 199
A19: Q2 (2 Jul 2025-30Sep 2025) | I19: Q2 (2 Jul 2025-30Sep 2025)
A20: Symbol | B20: Backtest P&L | C20: Total number of trades | D20: Number of wins | E20: Number of losses | I20: Symbol | J20: Backtest P&L | K20: Total number of trades | L20: Number of wins | M20: Number of losses
A21: JSWSTEEL | B21: 350.2 | C21: 24 | D21: 10 | E21: 14 | I21: JSWSTEEL | J21: 249.25 | K21: 33 | L21: 17 | M21: 16
A22: TATASTEEL | B22: 676.07 | C22: 19 | D22: 11 | E22: 8 | I22: TATASTEEL | J22: -945.3 | K22: 25 | L22: 11 | M22: 14
A23: JINDALSTEEL | B23: -120.44 | C23: 29 | D23: 13 | E23: 16 | I23: JINDALSTEEL | J23: -616.4 | K23: 27 | L23: 10 | M23: 17
A24: SAIL | B24: -128.29 | C24: 29 | D24: 10 | E24: 19 | I24: SAIL | J24: -282.57 | K24: 32 | L24: 14 | M24: 18
A25: JSL | B25: 535.55 | C25: 32 | D25: 16 | E25: 16 | I25: JSL | J25: -1507.7 | K25: 41 | L25: 13 | M25: 28
A26: NSLNSIP | B26: -1423.39 | C26: 32 | D26: 9 | E26: 23 | I26: NSLNSIP | J26: 1206.69 | K26: 36 | L26: 17 | M26: 19
A27: SARDAEN | B27: 981.4 | C27: 40 | D27: 19 | E27: 21 | I27: SARDAEN | J27: -1521.25 | K27: 43 | L27: 14 | M27: 29
A28: JAIBALAJI | B28: -1914.33 | C28: 28 | D28: 6 | E28: 22 | I28: JAIBALAJI | J28: 1773.53 | K28: 21 | L28: 10 | M28: 11
A29: PRAKASH | B29: 322.29 | C29: 34 | D29: 12 | E29: 22 | I29: PRAKASH | J29: 584.19 | K29: 34 | L29: 16 | M29: 18
A30: MUKANDLTD | B30: -3035.07 | C30: 48 | D30: 11 | E30: 37 | I30: MUKANDLTD | J30: 1191.58 | K30: 45 | L30: 19 | M30: 26
A31: TOTAL | C31: =SUM(C21:C30) -> 315 | D31: =SUM(D21:D30) -> 117 | E31: =SUM(E21:E30) -> 198 | I31: TOTAL | K31: =SUM(K21:K30) -> 337 | L31: =SUM(L21:L30) -> 141 | M31: =SUM(M21:M30) -> 196
A33: Q3 (1Oct 2025- 30Dec 2025) | I33: Q3 (1Oct 2025- 30Dec 2025)
A34: Symbol | B34: Backtest P&L | C34: Total number of trades | D34: Number of wins | E34: Number of losses | I34: Symbol | J34: Backtest P&L | K34: Total number of trades | L34: Number of wins | M34: Number of losses
A35: JSWSTEEL | B35: 878.95 | C35: 22 | D35: 11 | E35: 11 | I35: JSWSTEEL | J35: 1672.49 | K35: 26 | L35: 16 | M35: 10
A36: TATASTEEL | B36: 723.8 | C36: 21 | D36: 8 | E36: 13 | I36: TATASTEEL | J36: 712.12 | K36: 24 | L36: 12 | M36: 12
A37: JINDALSTEEL | B37: -347.34 | C37: 26 | D37: 11 | E37: 15 | I37: JINDALSTEEL | J37: 177.75 | K37: 28 | L37: 12 | M37: 16
A38: SAIL | B38: 613.59 | C38: 36 | D38: 12 | E38: 14 | I38: SAIL | J38: -65.17 | K38: 28 | L38: 12 | M38: 16
A39: JSL | B39: 396.45 | C39: 30 | D39: 13 | E39: 17 | I39: JSL | J39: -365.35 | K39: 31 | L39: 13 | M39: 18
A40: NSLNSIP | B40: -759.45 | C40: 39 | D40: 12 | E40: 27 | I40: NSLNSIP | J40: 677.79 | K40: 35 | L40: 18 | M40: 17
A41: SARDAEN | B41: 219.05 | C41: 27 | D41: 11 | E41: 16 | I41: SARDAEN | J41: 8.89 | K41: 30 | L41: 12 | M41: 18
A42: JAIBALAJI | B42: -1818.31 | C42: 25 | D42: 5 | E42: 20 | I42: JAIBALAJI | J42: 984.72 | K42: 22 | L42: 12 | M42: 10
A43: PRAKASH | B43: 1259.13 | C43: 25 | D43: 11 | E43: 14 | I43: PRAKASH | J43: 512.91 | K43: 25 | L43: 12 | M43: 13
A44: MUKANDLTD | B44: -1460.35 | C44: 26 | D44: 8 | E44: 18 | I44: MUKANDLTD | J44: 1027.09 | K44: 27 | L44: 13 | M44: 14
...

Sheet 8. Awesome Oscillator
A1: STEEL INDUSTRY (Awesome Oscillator Indicator BackTesting)
A3: BUY | I3: SELL
A5: Q1 (1 April 2025-30Jun 2025) | I5: Q1 (1 April 2025-30Jun 2025)
A6: Symbol | B6: Backtest P&L | C6: Total number of trades | D6: Number of wins | E6: Number of losses | I6: Symbol | J6: Backtest P&L | K6: Total number of trades | L6: Number of wins | M6: Number of losses
A7: JSWSTEEL | B7: -476.19 | C7: 64 | D7: 30 | E7: 34 | I7: JSWSTEEL | J7: 1103.74 | K7: 61 | L7: 33 | M7: 28
A8: TATASTEEL | B8: 2125.23 | C8: 62 | D8: 33 | E8: 29 | I8: TATASTEEL | J8: -272.53 | K8: 62 | L8: 28 | M8: 34
A9: JINDALSTEEL | B9: 1674.2 | C9: 66 | D9: 35 | E9: 31 | I9: JINDALSTEEL | J9: 173.89 | K9: 72 | L9: 33 | M9: 39
A10: SAIL | B10: 2831.37 | C10: 69 | D10: 35 | E10: 34 | I10: SAIL | J10: 37.7 | K10: 76 | L10: 31 | M10: 45
A11: JSL | B11: -457.09 | C11: 72 | D11: 32 | E11: 40 | I11: JSL | J11: -1419.65 | K11: 74 | L11: 28 | M11: 46
A12: NSLNSIP | B12: 1391.11 | C12: 69 | D12: 28 | E12: 41 | I12: NSLNSIP | J12: 895.47 | K12: 72 | L12: 36 | M12: 36
A13: SARDAEN | B13: 248.15 | C13: 75 | D13: 30 | E13: 45 | I13: SARDAEN | J13: 4462.89 | K13: 70 | L13: 36 | M13: 34
A14: JAIBALAJI | B14: -477.69 | C14: 71 | D14: 27 | E14: 44 | I14: JAIBALAJI | J14: 4566.95 | K14: 69 | L14: 37 | M14: 32
A15: PRAKASH | B15: 2913.53 | C15: 68 | D15: 31 | E15: 37 | I15: PRAKASH | J15: 2839.18 | K15: 66 | L15: 34 | M15: 32
A16: MUKANDLTD | B16: -1293.08 | C16: 81 | D16: 26 | E16: 55 | I16: MUKANDLTD | J16: -2058.71 | K16: 80 | L16: 28 | M16: 52
A17: TOTAL | C17: =SUM(C7:C16) -> 697 | D17: =SUM(D7:D16) -> 307 | E17: =SUM(E7:E16) -> 390 | I17: TOTAL | K17: =SUM(K7:K16) -> 702 | L17: =SUM(L7:L16) -> 324 | M17: =SUM(M7:M16) -> 378
A19: Q2 (2 Jul 2025-30Sep 2025) | I19: Q2 (2 Jul 2025-30Sep 2025)
A20: Symbol | B20: Backtest P&L | C20: Total number of trades | D20: Number of wins | E20: Number of losses | I20: Symbol | J20: Backtest P&L | K20: Total number of trades | L20: Number of wins | M20: Number of losses
A21: JSWSTEEL | B21: -1163.64 | C21: 70 | D21: 32 | E21: 38 | I21: JSWSTEEL | J21: -761.89 | K21: 69 | L21: 29 | M21: 40
A22: TATASTEEL | B22: -873.92 | C22: 62 | D22: 23 | E22: 39 | I22: TATASTEEL | J22: -376.34 | K22: 60 | L22: 31 | M22: 29
A23: JINDALSTEEL | B23: 74.75 | C23: 72 | D23: 32 | E23: 40 | I23: JINDALSTEEL | J23: 1549.34 | K23: 64 | L23: 30 | M23: 34
A24: SAIL | B24: -948.11 | C24: 74 | D24: 32 | E24: 42 | I24: SAIL | J24: -943.02 | K24: 72 | L24: 30 | M24: 42
A25: JSL | B25: 319.95 | C25: 84 | D25: 33 | E25: 51 | I25: JSL | J25: 254.14 | K25: 78 | L25: 33 | M25: 45
A26: NSLNSIP | B26: -2930.74 | C26: 79 | D26: 28 | E26: 51 | I26: NSLNSIP | J26: 2112.81 | K26: 76 | L26: 43 | M26: 33
A27: SARDAEN | B27: 256.3 | C27: 82 | D27: 33 | E27: 49 | I27: SARDAEN | J27: 2055.24 | K27: 83 | L27: 38 | M27: 45
A28: JAIBALAJI | B28: -3491.54 | C28: 82 | D28: 22 | E28: 60 | I28: JAIBALAJI | J28: 5503.63 | K28: 80 | L28: 44 | M28: 36
A29: PRAKASH | B29: -3776.1 | C29: 88 | D29: 24 | E29: 64 | I29: PRAKASH | J29: 3283.08 | K29: 84 | L29: 48 | M29: 36
A30: MUKANDLTD | B30: -1310.91 | C30: 82 | D30: 30 | E30: 52 | I30: MUKANDLTD | J30: 3313.26 | K30: 76 | L30: 37 | M30: 39
A31: TOTAL | C31: =SUM(C21:C30) -> 775 | D31: =SUM(D21:D30) -> 289 | E31: =SUM(E21:E30) -> 486 | I31: TOTAL | K31: =SUM(K21:K30) -> 742 | L31: =SUM(L21:L30) -> 363 | M31: =SUM(M21:M30) -> 379
A33: Q3 (1Oct 2025- 30Dec 2025) | I33: Q3 (1Oct 2025- 30Dec 2025)
A34: Symbol | B34: Backtest P&L | C34: Total number of trades | D34: Number of wins | E34: Number of losses | I34: Symbol | J34: Backtest P&L | K34: Total number of trades | L34: Number of wins | M34: Number of losses
A35: JSWSTEEL | B35: 383.3 | C35: 57 | D35: 28 | E35: 29 | I35: JSWSTEEL | J35: 822.84 | K35: 61 | L35: 31 | M35: 30
A36: TATASTEEL | B36: -1034.96 | C36: 63 | D36: 25 | E36: 38 | I36: TATASTEEL | J36: 1013.97 | K36: 55 | L36: 28 | M36: 27
A37: JINDALSTEEL | B37: -1495.69 | C37: 71 | D37: 32 | E37: 39 | I37: JINDALSTEEL | J37: 1564.69 | K37: 64 | L37: 31 | M37: 33
A38: SAIL | B38: 553.21 | C38: 68 | D38: 31 | E38: 37 | I38: SAIL | J38: 577.5 | K38: 66 | L38: 32 | M38: 34
A39: JSL | B39: -575.29 | C39: 74 | D39: 29 | E39: 45 | I39: JSL | J39: 1153.39 | K39: 67 | L39: 32 | M39: 35
A40: NSLNSIP | B40: -143.11 | C40: 69 | D40: 27 | E40: 42 | I40: NSLNSIP | J40: 1626.1 | K40: 63 | L40: 39 | M40: 24
A41: SARDAEN | B41: -1161.39 | C41: 76 | D41: 29 | E41: 47 | I41: SARDAEN | J41: 2301.14 | K41: 72 | L41: 35 | M41: 37
A42: JAIBALAJI | B42: -1428.14 | C42: 83 | D42: 29 | E42: 54 | I42: JAIBALAJI | J42: 3887.44 | K42: 71 | L42: 38 | M42: 33
A43: PRAKASH | B43: -2230.7 | C43: 66 | D43: 21 | E43: 45 | I43: PRAKASH | J43: 4390.43 | K43: 63 | L43: 39 | M43: 24
A44: MUKANDLTD | B44: -634.71 | C44: 70 | D44: 30 | E44: 40 | I44: MUKANDLTD | J44: -1722.73 | K44: 79 | L44: 26 | M44: 53
...

Sheet 9.Bollinger Bands
A1: STEEL INDUSTRY (Bollinger Bands Indicator BackTesting)
A3: BUY | I3: SELL
A5: Q1 (1 April 2025-30Jun 2025) | I5: Q1 (1 April 2025-30Jun 2025)
A6: Symbol | B6: Backtest P&L | C6: Total number of trades | D6: Number of wins | E6: Number of losses | I6: Symbol | J6: Backtest P&L | K6: Total number of trades | L6: Number of wins | M6: Number of losses
A7: JSWSTEEL | B7: -3134.04 | C7: 80 | D7: 27 | E7: 53 | I7: JSWSTEEL | J7: 530.34 | K7: 79 | L7: 37 | M7: 42
A8: TATASTEEL | B8: -1117.93 | C8: 66 | D8: 29 | E8: 37 | I8: TATASTEEL | J8: 625.4 | K8: 78 | L8: 37 | M8: 41
A9: JINDALSTEEL | B9: -1643.09 | C9: 88 | D9: 30 | E9: 58 | I9: JINDALSTEEL | J9: -30.1 | K9: 86 | L9: 38 | M9: 48
A10: SAIL | B10: 526.32 | C10: 79 | D10: 33 | E10: 46 | I10: SAIL | J10: 508.57 | K10: 92 | L10: 42 | M10: 50
A11: JSL | B11: -4301.29 | C11: 90 | D11: 31 | E11: 59 | I11: JSL | J11: -2079.05 | K11: 96 | L11: 35 | M11: 61
A12: NSLNSIP | B12: -928.16 | C12: 87 | D12: 37 | E12: 50 | I12: NSLNSIP | J12: 378.27 | K12: 106 | L12: 49 | M12: 57
A13: SARDAEN | B13: -3237.39 | C13: 104 | D13: 35 | E13: 69 | I13: SARDAEN | J13: 976.94 | K13: 100 | L13: 46 | M13: 54
A14: JAIBALAJI | B14: -4580.8 | C14: 103 | D14: 33 | E14: 70 | I14: JAIBALAJI | J14: 1654.14 | K14: 107 | L14: 46 | M14: 61
A15: PRAKASH | B15: -91.22 | C15: 95 | D15: 36 | E15: 59 | I15: PRAKASH | J15: 2817.28 | K15: 105 | L15: 50 | M15: 55
A16: MUKANDLTD | B16: 1077.79 | C16: 94 | D16: 38 | E16: 56 | I16: MUKANDLTD | J16: 1853.05 | K16: 115 | L16: 51 | M16: 64
A17: TOTAL | C17: =SUM(C7:C16) -> 886 | D17: =SUM(D7:D16) -> 329 | E17: =SUM(E7:E16) -> 557 | I17: TOTAL | K17: =SUM(K7:K16) -> 964 | L17: =SUM(L7:L16) -> 431 | M17: =SUM(M7:M16) -> 533
A19: Q2 (2 Jul 2025-30Sep 2025) | I19: Q2 (2 Jul 2025-30Sep 2025)
A20: Symbol | B20: Backtest P&L | C20: Total number of trades | D20: Number of wins | E20: Number of losses | I20: Symbol | J20: Backtest P&L | K20: Total number of trades | L20: Number of wins | M20: Number of losses
A21: JSWSTEEL | B21: 1160.04 | C21: 63 | D21: 35 | E21: 28 | I21: JSWSTEEL | J21: 340.25 | K21: 77 | L21: 42 | M21: 35
A22: TATASTEEL | B22: -2121.41 | C22: 66 | D22: 27 | E22: 39 | I22: TATASTEEL | J22: -1071.56 | K22: 69 | L22: 32 | M22: 37
A23: JINDALSTEEL | B23: 116.6 | C23: 69 | D23: 35 | E23: 34 | I23: JINDALSTEEL | J23: -972.45 | K23: 81 | L23: 34 | M23: 47
A24: SAIL | B24: -618.74 | C24: 75 | D24: 36 | E24: 39 | I24: SAIL | J24: 1212.79 | K24: 78 | L24: 38 | M24: 40
A25: JSL | B25: 2135.6 | C25: 85 | D25: 44 | E25: 41 | I25: JSL | J25: -1711.45 | K25: 86 | L25: 33 | M25: 53
A26: NSLNSIP | B26: -1961.05 | C26: 89 | D26: 34 | E26: 55 | I26: NSLNSIP | J26: 5092.48 | K26: 99 | L26: 54 | M26: 45
A27: SARDAEN | B27: 4857.14 | C27: 96 | D27: 33 | E27: 63 | I27: SARDAEN | J27: 1504.74 | K27: 95 | L27: 43 | M27: 52
A28: JAIBALAJI | B28: -4779.8 | C28: 110 | D28: 33 | E28: 77 | I28: JAIBALAJI | J28: 5865.76 | K28: 89 | L28: 51 | M28: 38
A29: PRAKASH | B29: -307.48 | C29: 83 | D29: 26 | E29: 57 | I29: PRAKASH | J29: 5913.1 | K29: 107 | L29: 58 | M29: 49
A30: MUKANDLTD | B30: -3601.78 | C30: 106 | D30: 37 | E30: 69 | I30: MUKANDLTD | J30: 3413.82 | K30: 93 | L30: 43 | M30: 50
A31: TOTAL | C31: =SUM(C21:C30) -> 842 | D31: =SUM(D21:D30) -> 340 | E31: =SUM(E21:E30) -> 502 | I31: TOTAL | K31: =SUM(K21:K30) -> 874 | L31: =SUM(L21:L30) -> 428 | M31: =SUM(M21:M30) -> 446
A33: Q3 (1Oct 2025- 30Dec 2025) | I33: Q3 (1Oct 2025- 30Dec 2025)
A34: Symbol | B34: Backtest P&L | C34: Total number of trades | D34: Number of wins | E34: Number of losses | I34: Symbol | J34: Backtest P&L | K34: Total number of trades | L34: Number of wins | M34: Number of losses
A35: JSWSTEEL | B35: -2682.04 | C35: 76 | D35: 30 | E35: 46 | I35: JSWSTEEL | J35: 1606.39 | K35: 72 | L35: 39 | M35: 33
A36: TATASTEEL | B36: -1655.17 | C36: 71 | D36: 29 | E36: 42 | I36: TATASTEEL | J36: 575.1 | K36: 65 | L36: 31 | M36: 34
A37: JINDALSTEEL | B37: -2180.09 | C37: 75 | D37: 34 | E37: 41 | I37: JINDALSTEEL | J37: 1035.89 | K37: 74 | L37: 37 | M37: 37
A38: SAIL | B38: 2107.18 | C38: 86 | D38: 45 | E38: 41 | I38: SAIL | J38: 2426.86 | K38: 81 | L38: 43 | M38: 38
A39: JSL | B39: -57.39 | C39: 76 | D39: 35 | E39: 41 | I39: JSL | J39: -365 | K39: 83 | L39: 37 | M39: 46
A40: NSLNSIP | B40: -1245.03 | C40: 74 | D40: 29 | E40: 45 | I40: NSLNSIP | J40: -252.48 | K40: 96 | L40: 47 | M40: 49
A41: SARDAEN | B41: -1306.99 | C41: 90 | D41: 34 | E41: 56 | I41: SARDAEN | J41: 2271.24 | K41: 104 | L41: 49 | M41: 55
A42: JAIBALAJI | B42: -3963.43 | C42: 101 | D42: 37 | E42: 64 | I42: JAIBALAJI | J42: 4499.26 | K42: 96 | L42: 53 | M42: 43
A43: PRAKASH | B43: -3172.78 | C43: 88 | D43: 27 | E43: 61 | I43: PRAKASH | J43: 5153.37 | K43: 81 | L43: 47 | M43: 34
A44: MUKANDLTD | B44: 1035.41 | C44: 85 | D44: 41 | E44: 44 | I44: MUKANDLTD | J44: 2293.35 | K44: 95 | L44: 47 | M44: 48
...

Sheet 10.CPR
A1: STEEL INDUSTRY (CPR Indicator BackTesting)
A3: BUY | I3: SELL
A5: Q1 (1 April 2025-30Jun 2025) | I5: Q1 (1 April 2025-30Jun 2025)
A6: Symbol | B6: Backtest P&L | C6: Total number of trades | D6: Number of wins | E6: Number of losses | I6: Symbol | J6: Backtest P&L | K6: Total number of trades | L6: Number of wins | M6: Number of losses
A7: JSWSTEEL | B7: -1613.39 | C7: 35 | D7: 11 | E7: 24 | I7: JSWSTEEL | J7: 503.09 | K7: 32 | L7: 18 | M7: 14
A8: TATASTEEL | B8: 1144 | C8: 40 | D8: 19 | E8: 21 | I8: TATASTEEL | J8: -112.96 | K8: 23 | L8: 9 | M8: 14
A9: JINDALSTEEL | B9: -164.14 | C9: 38 | D9: 15 | E9: 22 | I9: JINDALSTEEL | J9: 3098.74 | K9: 28 | L9: 19 | M9: 9
A10: SAIL | B10: 3296.81 | C10: 46 | D10: 24 | E10: 22 | I10: SAIL | J10: -402.91 | K10: 34 | L10: 12 | M10: 21
A11: JSL | B11: 292.1 | C11: 45 | D11: 17 | E11: 28 | I11: JSL | J11: -1929.4 | K11: 31 | L11: 7 | M11: 24
A12: NSLNSIP | B12: 430.99 | C12: 31 | D12: 13 | E12: 18 | I12: NSLNSIP | J12: -885.39 | K12: 29 | L12: 10 | M12: 19
A13: SARDAEN | B13: -2425.99 | C13: 53 | D13: 14 | E13: 39 | I13: SARDAEN | J13: 828.54 | K13: 28 | L13: 18 | M13: 20
A14: JAIBALAJI | B14: 652.61 | C14: 38 | D14: 17 | E14: 21 | I14: JAIBALAJI | J14: 1982.55 | K14: 36 | L14: 20 | M14: 16
A15: PRAKASH | B15: -180.32 | C15: 51 | D15: 19 | E15: 32 | I15: PRAKASH | J15: 3172.69 | K15: 33 | L15: 22 | M15: 11
A16: MUKANDLTD | B16: 1425.87 | C16: 42 | D16: 18 | E16: 24 | I16: MUKANDLTD | J16: -2771.59 | K16: 36 | L16: 8 | M16: 28
A17: TOTAL | C17: =SUM(C7:C16) -> 419 | D17: =SUM(D7:D16) -> 167 | E17: =SUM(E7:E16) -> 251 | I17: TOTAL | K17: =SUM(K7:K16) -> 310 | L17: =SUM(L7:L16) -> 143 | M17: =SUM(M7:M16) -> 176
A19: Q2 (2 Jul 2025-30Sep 2025) | I19: Q2 (2 Jul 2025-30Sep 2025)
A20: Symbol | B20: Backtest P&L | C20: Total number of trades | D20: Number of wins | E20: Number of losses | I20: Symbol | J20: Backtest P&L | K20: Total number of trades | L20: Number of wins | M20: Number of losses
A21: JSWSTEEL | B21: 13.94 | C21: 49 | D21: 24 | E21: 25 | I21: JSWSTEEL | J21: -673.89 | K21: 38 | L21: 18 | M21: 20
A22: TATASTEEL | B22: -390.44 | C22: 38 | D22: 15 | E22: 22 | I22: TATASTEEL | J22: 192.25 | K22: 34 | L22: 17 | M22: 17
A23: JINDALSTEEL | B23: -827.79 | C23: 45 | D23: 18 | E23: 27 | I23: JINDALSTEEL | J23: -210.8 | K23: 39 | L23: 17 | M23: 22
A24: SAIL | B24: -174.56 | C24: 40 | D24: 18 | E24: 22 | I24: SAIL | J24: 583.76 | K24: 35 | L24: 16 | M24: 19
A25: JSL | B25: 170.8 | C25: 43 | D25: 19 | E25: 24 | I25: JSL | J25: -460.3 | K25: 31 | L25: 13 | M25: 18
A26: NSLNSIP | B26: -2383.7 | C26: 51 | D26: 16 | E26: 35 | I26: NSLNSIP | J26: 1874.86 | K26: 31 | L26: 19 | M26: 12
A27: SARDAEN | B27: -1013.79 | C27: 54 | D27: 16 | E27: 38 | I27: SARDAEN | J27: -1750.95 | K27: 44 | L27: 18 | M27: 26
A28: JAIBALAJI | B28: -1513.93 | C28: 49 | D28: 15 | E28: 34 | I28: JAIBALAJI | J28: 4762.93 | K28: 45 | L28: 28 | M28: 17
A29: PRAKASH | B29: -2550.04 | C29: 63 | D29: 16 | E29: 47 | I29: PRAKASH | J29: -427.26 | K29: 50 | L29: 22 | M29: 28
A30: MUKANDLTD | B30: -3412.47 | C30: 58 | D30: 17 | E30: 41 | I30: MUKANDLTD | J30: 443.63 | K30: 44 | L30: 19 | M30: 25
A31: TOTAL | C31: =SUM(C21:C30) -> 490 | D31: =SUM(D21:D30) -> 174 | E31: =SUM(E21:E30) -> 315 | I31: TOTAL | K31: =SUM(K21:K30) -> 391 | L31: =SUM(L21:L30) -> 187 | M31: =SUM(M21:M30) -> 204
A33: Q3 (1Oct 2025- 30Dec 2025) | I33: Q3 (1Oct 2025- 30Dec 2025)
A34: Symbol | B34: Backtest P&L | C34: Total number of trades | D34: Number of wins | E34: Number of losses | I34: Symbol | J34: Backtest P&L | K34: Total number of trades | L34: Number of wins | M34: Number of losses
A35: JSWSTEEL | B35: -45.59 | C35: 41 | D35: 19 | E35: 22 | I35: JSWSTEEL | J35: 7.99 | K35: 34 | L35: 18 | M35: 16
A36: TATASTEEL | B36: -597.57 | C36: 35 | D36: 15 | E36: 20 | I36: TATASTEEL | J36: 1582.51 | K36: 31 | L36: 19 | M36: 12
A37: JINDALSTEEL | B37: -615.6 | C37: 39 | D37: 17 | E37: 22 | I37: JINDALSTEEL | J37: -831.1 | K37: 38 | L37: 15 | M37: 23
A38: SAIL | B38: -1397.76 | C38: 44 | D38: 17 | E38: 27 | I38: SAIL | J38: 1408.43 | K38: 38 | L38: 18 | M38: 20
A39: JSL | B39: 1558.35 | C39: 38 | D39: 20 | E39: 18 | I39: JSL | J39: 237.54 | K39: 32 | L39: 14 | M39: 18
A40: NSLNSIP | B40: -1828.16 | C40: 35 | D40: 11 | E40: 24 | I40: NSLNSIP | J40: 2447.03 | K40: 28 | L40: 20 | M40: 8
A41: SARDAEN | B41: -1328.14 | C41: 47 | D41: 15 | E41: 31 | I41: SARDAEN | J41: 2077.44 | K41: 39 | L41: 23 | M41: 16
A42: JAIBALAJI | B42: -1725.3 | C42: 41 | D42: 12 | E42: 29 | I42: JAIBALAJI | J42: 1411.28 | K42: 35 | L42: 21 | M42: 14
A43: PRAKASH | B43: -2791.83 | C43: 39 | D43: 10 | E43: 29 | I43: PRAKASH | J43: 615.44 | K43: 31 | L43: 15 | M43: 16
A44: MUKANDLTD | B44: -2455.27 | C44: 53 | D44: 17 | E44: 35 | I44: MUKANDLTD | J44: -314.95 | K44: 40 | L44: 16 | M44: 24
...

Sheet Ranking
A1: STEEL INDUSTRY Ranking
A3: S. No. | B3: Name of the Indicator | C3: Probability of Win | D3: Probability of Loss | E3: Ranking
A4: 1 | B4: Super Trend | C4: ='1.Super Trend'!J66 -> 0.43159041 | D4: ='1.Super Trend'!J67 -> 0.56840959 | E4: 4
A5: 2 | B5: RSI | C5: ='2.RSI'!J66 -> 0.42134682 | D5: ='2.RSI'!J67 -> 0.58583977 | E5: 8
A6: 3 | B6: Fibonacci Moving Average | C6: ='3. Fibonacci MA'!J66 -> 0.45681954 | D6: ='3. Fibonacci MA'!J67 -> 0.54318046 | E6: 1
A7: 4 | B7: VWAP | C7: ='4.VWAP'!J66 -> 0.36671749 | D7: ='4.VWAP'!J67 -> 0.54368477 | E7: 10
A8: 5 | B8: MACD | C8: ='5.MACD'!J66 -> 0.43101565 | D8: ='5.MACD'!J67 -> 0.56898435 | E8: 7
A9: 6 | B9: Stochastic RSI | C9: ='6.Stochastic RSI'!J66 -> 0.42987507 | D9: ='6.Stochastic RSI'!J67 -> 0.57620858 | E9: 5
A10: 7 | B10: Pivot point Standard | C10: ='7.Pivot Point Standard'!J66 -> 0.41772152 | D10: ='7.Pivot Point Standard'!J67 -> 0.59697836 | E10: 9
A11: 8 | B11: Awesome Oscillator | C11: ='8. Awesome Oscillator'!J66 -> 0.44371797 | D11: ='8. Awesome Oscillator'!J67 -> 0.55628203 | E11: 2
A12: 9 | B12: Bollinger Bands | C12: ='9.Bollinger Bands'!J66 -> 0.43431902 | D12: ='9.Bollinger Bands'!J67 -> 0.56568098 | E12: 3
A13: 10 | B13: CPR | C13: ='10.CPR'!J66 -> 0.42534943 | D13: ='10.CPR'!J67 -> 0.57623888 | E13: 6
A15: The Steel Industry stocks were backtested using 10 technical indicators from 1st April 2025 to 21st March 2026. Among all the indicators, Fibonacci Moving Average showed the highest probability of win at 44.697%, making it the most effective indicator for identifying profitable trading opportunities in the Steel Industry. The Awesome Oscillator ranked second with a win probability of 44.372%, indicating its strong effectiveness in capturing market momentum and trend movements in the sector. Therefore,these two indicators are best for Steel Sector
